<?xml version='1.0'?>
<robot xmlns:xacro="http://ros.org/wiki/xacro" name="central_controller">
<!--x=92.09, y=-3.12, z=0.55, r=-0.0, p= 0.0, Y=0.613 -->
<xacro:arg name="namespace" default=""/>
  <!--<link name="world"/>-->
  <gazebo>
    <static>true</static>
  </gazebo>

  <link name="$(arg namespace)base_link">
    <inertial>
      <origin xyz="0 0 0" rpy="0 0 0"/>
      <mass value="10"/>
      <inertia ixx="0.001" ixy="0.0" ixz="0.0" iyy="0.001" iyz="0.0" izz="0.001" />
    </inertial>
    <collision name="collision">
      <geometry>
         <box size="0.1 0.1 0.1"/>
      </geometry>
    </collision>
    <visual name="visual">
        <geometry>
            <mesh filename="package://prius_description/meshes/hokuyo.dae"/>
        </geometry>
    </visual>
  </link>

  <!-- Add the fixed joint between "world" and "base_link"
  <joint name="fixed_joint" type="fixed">
    <parent link="world"/>
    <child link="$(arg namespace)base_link"/>
    <origin xyz="0 0 0" rpy="0 0 0"/>
  </joint>
   -->
<link name="$(arg namespace)laser_link">
    <inertial>
      <origin xyz="0 0 0" rpy="0 0 0"/>
      <mass value="10"/>
      <inertia ixx="0.001" ixy="0" ixz="0" iyy="0.001" iyz="0" izz="0.001" />
    </inertial>
  </link>
    
  <joint name="laser_joint" type="fixed">
    <parent link="$(arg namespace)base_link"/>
    <child link="$(arg namespace)laser_link"/>
    <origin xyz="0 0 0" rpy="0 0 0"/>
  </joint>

  <gazebo reference="$(arg namespace)laser_link">
    <sensor name="laser_hokuyo" type="ray">
      <always_on>true</always_on>
      <visualize>false</visualize>
      <publish_rate>1.0</publish_rate>
      <ray>
        <scan>
          <horizontal>
            <samples>65</samples>
            <resolution>0.8</resolution>
            <min_angle>-0.7</min_angle>
            <max_angle>0.8</max_angle>
          </horizontal>
        </scan>
        <range>
          <min>0.2</min>
          <max>10</max>
          <resolution>0.015000</resolution>
        </range>
        <noise>
          <type>gaussian</type>
          <mean>0.0</mean>
          <stddev>0.01</stddev>
        </noise>
      </ray>
        <plugin name="gazebo_ros_head_hokuyo_controller" filename="libgazebo_ros_ray_sensor.so">
          <ros>
            <remapping>~/out:=outside_scan</remapping>
          </ros>
            <output_type>sensor_msgs/LaserScan</output_type>
            <frame_name>$(arg namespace)laser_link</frame_name>
        </plugin>
    </sensor>
  </gazebo>



  <link name="$(arg namespace)left_wheel">
      <inertial>
        <origin xyz="0 0 0" rpy="0 0 0"/>
        <mass value="10"/>
        <inertia ixx="0.001" ixy="0.0" ixz="0.0" iyy="0.001" iyz="0.0" izz="0.001" />
      </inertial>
      <visual>
      <!--
        <geometry>
          <cylinder length="0.05" radius="0.05"/>
        </geometry>
      -->
        <material name="gray">
          <color rgba="0.5 0.5 0.5 1"/>
        <!--
          <friction>
            <ode>
              <mu>1.0</mu>
            </ode>
          </friction>
        -->
        </material>
      </visual>
      <collision>
        <geometry>
          <cylinder length="0.05" radius="0.05"/>
        </geometry>
      </collision>
    </link>

    <link name="$(arg namespace)right_wheel">
      <inertial>
        <origin xyz="0 0 0" rpy="0 0 0"/>
        <mass value="10"/>
        <inertia ixx="0.001" ixy="0.0" ixz="0.0" iyy="0.001" iyz="0.0" izz="0.001" />
      </inertial>
      <visual>
      <!--
        <geometry>
          <cylinder length="0.05" radius="0.05"/>
        </geometry>
      -->  
        <material name="gray">
          <color rgba="0.5 0.5 0.5 1"/>
        <!--
          <friction>
            <ode>
              <mu>1.0</mu>
            </ode>
          </friction>
        -->
        </material>
      </visual>
      <collision>
        <geometry>
          <cylinder length="0.05" radius="0.05"/>
        </geometry>
      </collision>
    </link>

    <joint name="left_wheel_joint" type="continuous">
      <parent link="$(arg namespace)base_link"/>
      <child link="$(arg namespace)left_wheel"/>
      <origin xyz="0 0 0" rpy="0 0 0" />
      <axis xyz="1 0 0" />
    </joint>

    <joint name="right_wheel_joint" type="continuous">
      <parent link="$(arg namespace)base_link"/>
      <child link="$(arg namespace)right_wheel"/>
      <origin xyz="0 0 0" rpy="0 0 0" />
      <axis xyz="1 0 0" />
    </joint>

    <!-- GAZEBO -->
    <gazebo>
      <plugin name="joint_states" filename="libgazebo_ros_joint_state_publisher.so">
        <ros>
            <remapping>~/out:=joint_states</remapping>
            <!--<namespace>sensor</namespace>-->
        </ros>
        <update_rate>30</update_rate>
        <joint_name>left_wheel_joint</joint_name>
        <joint_name>right_wheel_joint</joint_name>
      </plugin>
    </gazebo>

    <gazebo>
      <plugin name='diff_drive' filename='libgazebo_ros_diff_drive.so'>
        <!-- wheels -->
        <left_joint>left_wheel_joint</left_joint>
        <right_joint>right_wheel_joint</right_joint>
        
        <!-- kinematics 
        <wheel_separation>0.0</wheel_separation>
        <wheel_diameter>0.0</wheel_diameter>
        -->
        <!-- limits -->
        <max_wheel_torque>0</max_wheel_torque>
        <max_wheel_acceleration>0.0</max_wheel_acceleration>

        <!-- output -->
        <publish_odom>true</publish_odom>
        <publish_odom_tf>true</publish_odom_tf>
        <publish_wheel_tf>true</publish_wheel_tf>

        <odometry_frame>$(arg namespace)odom</odometry_frame>
        <robot_base_frame>$(arg namespace)base_link</robot_base_frame>

      </plugin>
    </gazebo>
</robot>
